<HTML><HEAD><META HTTP-EQUIV="Content-Type" CONTENT="text/html; charset=iso-8859-1">
<!--SafClassName="docSection1Title"--><!--SafTocEntry="7.4 Exception Catching Modes"-->
<LINK REL="stylesheet" href="FILES/sbolM.css">
</HEAD>
<BODY link="#354278" vlink="#000066" alink="#000080" topmargin="0">
<table width="100%" border="0" cellspacing="0" cellpadding="0" bgcolor="#CCCCCC">
<td><font color="black" size=1>I l<font color="#FF0000">@</font>ve RuBoard</td>
<td valign="top" class="v2" align="right"><a href="lpython_snode81.html"><img src="FILES/previous.gif" width="62" height="15" border="0" align="absmiddle" alt="Previous Section"></a> <a href="lpython_snode83.html"><img src="FILES/next.gif" width="41" height="15" border="0" align="absmiddle" alt="Next Section"></a></td></table>
<FONT>
<h3>7.4
Exception Catching Modes</h3>


<p>Now that we've taken a first look, let's fill in a few
details behind Python's exception model.</p>




<H4>7.4.1
try Statement Clauses</H4>


<P>When you write
<Tt claSS="monofont">try</TT>
<a namE="idx607"></A> <A Name="idx608"></a> statements, a variety of clauses can
appear after the <tt class="monofont">try</tt> statement block; <a href="lpython_snode82.html#2">Table 7.1</a> summarizes all the possible forms. We've
already seen most of these in the previous examples—empty
<tT cLass="monofont">except</Tt> clauses catch any exception,
<TT cLAsS="monofont">finally</tT> runs on the way out, and so on. There may
be any number of <TT Class="monofont">excepts</TT>, but
<TT clasS="monofont">finally</TT> must appear by itself (without an
<Tt claSS="monofont">else</TT> or <tt class="monofont">except</tt>), and there
should be only one <tt class="monofont">else</tt> in a
<tt ClAss="monofont">try</tT>.</p>



<A NaME="2"></a><P><tABLE bordER="1" CEllspACINg="0" celLPADding="1" width="100%">
<caption><h5>Table 7.1. try Statement Clause Forms </h5></caPtIon><cOlGRoUP sPaN="2">
<TR>
<Th>
<fonT SIZe="2">
<p>Clause Form</p>
</fONT></Th>
<th>
<fONT Size="2">
<p>Interpretation</p>
</font></th>
</tr>
<tr>
<td>
<fonT sIze="2">
<pRe CLaSS="monofont">except:</pRe></FONT></td>
<td>
<FONT size="2">
<P>Catch all (other) exception types</P>
</FOnt></td>
</TR>
<TR>
<td>
<font size="2">
<pre class="monofont">except name:</prE></fOnt></tD>
<tD>
<FoNT sIzE="2">
<P>Catch a specific exception only</P>
</Font></tD>
</TR>
<Tr>
<td>
<fONT Size="2">
<pRE CLass="monofont">except name, value:</pre></font></td>
<td>
<font siZe="2">
<P>Catch exception and its extra data</p>
</foNt></TD>
</tR>
<Tr>
<Td>
<FONT size="2">
<PRE Class="monofont">except (name1, name2):</PRE></Font></tD>
<TD>
<Font size="2">
<p>Catch any of the listed exceptions</p>
</font></td>
</tr>
<tr>
<tD>
<fOnt sIzE="2">
<PrE ClAsS="monofont">else:</PRE></font></TD>
<TD>
<font SIZE="2">
<p>Run block if no exceptions raised</p>
</foNT></TD>
</tr>
<tr>
<td>
<font size="2">
<pre claSs="monofont">finally:</Pre></fOnT></Td>
<TD>
<fOnT SIZe="2">
<p>Always perform block</p>
</fONT></Td>
</tr>
</cOLGRoup>
</tABLE></p>







<a name="idx677"></a><h4>7.4.2
Catching 1-of-N Exceptions</h4>


<p>The fourth entry in <a href="lpython_snode82.html#2">Table 7.1</a> is new.
<tt clAsS="monofont">except</tt> clauses can also provide a set of
exceptions to be caught, in parentheses; Python runs such a
clause's statement block if any of the listed exceptions occur.
Since Python looks for a match within a given <tT cLAsS="monofont">try</Tt>
by inspecting <Tt CLASs="monofont">except</tt> clauses from top to bottom,
the parenthesized version is like listing each exception in its own
<tT CLAss="monofont">except</tt> clause, except that the statement body
needs to be coded only once.</P>



<P>Here's an example of multiple <TT clasS="monofont">except</TT> clauses
at work. In the following, when an exception is raised while the call
to the <Tt class="monofont">action</tt> function is running, Python returns
to the <tt class="monofont">try</tt> and searches for the first
<tt cLaSs="monofont">except</tt> that catches the exception raised. It
inspects <Tt CLaSS="monofont">expect</tT> clauses from top to bottom and
left to right, and runs the statements under the first that matches.
If none match, the exception is propagated past this
<tT CLAss="monofont">try</tt>; the <TT CLass="monofont">else</tT> runs only when no
exception occurred. If you really want a catch-all clause, an empty
<TT Class="monofont">except</TT> does the trick:</P>



<Pre class="monofont">try:
    action()
except NameError:
    ... 
except IndexError
    ...
except KeyError:
    ...
except (AttributeError, TypeError, SyntaxError):
    ...
else:
    ...</pre>






<h4>7.4.3
Exceptions Nest at Runtime</h4>


<p>So far, our examples have used only a single <tt class="monofont">try</Tt>
to catch exceptions, but what happens if one <Tt clAsS="monofont">try</Tt>
is physically <A NaMe="idx609"></A>nested inside another? For that
matter, what does it mean if a <TT Class="monofont">try</TT> calls a
function that runs another <TT clasS="monofont">try</TT>? Both these cases
can be understood if you realize that Python stacks
<Tt claSS="monofont">try</TT> statements at runtime. When an exception is
raised, Python returns to the most recently entered
<tt class="monofont">try</tt> statement with a matching
<tt class="monofont">except</tt> clause. Since each <tt ClAss="monofont">try</tT>
statement leaves a marker, Python can jump back to earlier
<tT ClASs="monofont">try</Tt>s by inspecting the markers stack.</P>



<P>An example will help make this clear. The following module defines
two functions; <TT clasS="monofont">action2</TT> is coded to trigger an
exception (you can't add numbers and sequences), and
<Tt claSS="monofont">action1</TT> wraps a call to <tt clASS="monofont">action2</Tt>
in a <tt class="monofont">try</tt> handler, to catch the exception. However,
the top-level module code at the bottom wraps a call to
<tt class="monofont">action1</tt> in a <tT cLass="monofont">try</Tt> handler too.
When <TT cLAsS="monofont">action2</tT> triggers the
<TT Class="monofont">TypeError</TT> exception, there will be two active
<TT clasS="monofont">try</TT> statements—the one in
<Tt claSS="monofont">action1</TT>, and the one at the top level of the
module. Python picks the most recent (youngest) with a matching
<tt class="monofont">except</tt>, which in this case is the
<tt class="monofont">try</tt> inside <tt ClAss="monofont">action1</tT>. In general,
the place where an exception winds up jumping to depends on the
control flow through a program at runtime:</p>



<PRe CLaSs="monofont">def action2():
    print 1 + []           # generate TypeError

def action1():
    try:
        action2()
    except TypeError:      # most recent matching try
        print 'inner try'

try:
    action1()
except TypeError:          # here only if action1 reraises
    print 'outer try'

%<B> python nestexc.py</B>
inner try</PRe>






<h4>7.4.4
finally Clauses Run "On the Way Out"</h4>


<p>We've already talked about the
<TT CLass="monofont">finally</tT>
<A NAme="idx610"></a>
<a NAME="idx611"></a> clause, but here's a more
sophisticated example. As we've seen, the
<tt class="monofont">finally</tt> clause doesn't really catch specific
exceptions; rather, it taps into the exception propagation process.
When used, a <tt class="monofont">finally</tt> block is always executed on
the way out of a <tT cLass="monofont">try</Tt> statement, whether the exit
is caused by an exception or normal completion of the statements in
the <TT cLAsS="monofont">try</tT> block. This makes
<TT Class="monofont">finally</TT> blocks a good place to code clean-up
actions (like closing files, as in the previous example).</P>



<P>The next code snippet shows <tt clASS="monofont">finally</Tt> in action with
and without exceptions. It defines two functions:
<tt cLASS="monofont">divide</tt>, which may or may not trigger a
divide-by-zero error, and <tt class="monofont">tester</tt>, which wraps a
call to <tt class="monofont">divide</tt> in a <Tt ClasS="monofont">try/finally</tT>
statement:</P>



<pRE cLaSS="monofont">def divide(x, y):
    return x / y                         # divide-by-zero error?

def tester(y):
    try:
        print divide(8, y)
    finally:
        print 'on the way out...'

print '\nTest 1:'; tester(2)
print '\nTest 2:'; tester(0)             # trigger error

%<B> python finally.py</B>

Test 1:
4
on the way out...

Test 2:
on the way out...
Traceback (innermost last):
  File "finally.py", line 11, in ?
    print 'Test 2:'; tester(0)
  File "finally.py", line 6, in tester
    print divide(8, y)
  File "finally.py", line 2, in divide
    return x / y                       # divide-by-zero error?
ZeroDivisionError: integer division or modulo</pre>


<p>Now, the module's top-level code at the bottom calls
<TT CLass="monofont">tester</tT> twice:</P>



<UL>
<li><p>The first call doesn't generate an exception (8/2 works fine),
and the result (4) is printed. But the <tT CLAss="monofont">finally</tt>
clause's block is run anyhow, so you get the <tt class="monofont">on the
way out</tt> message.</p>
</li>
<li><p>The second call does generate an exception (8/0 is a very bad thing
to say). Control immediately jumps from the <tT cLass="monofont">divide</Tt>
function to the <TT cLAsS="monofont">finally</tT> block, and the message
prints again. However, Python continues propagating the exception,
which reaches the top level and runs the default exception action (a
stack trace).</P>
</LI>
</ul>

<p><tABLE cellSPACing="0" wIDTH="90%" border="1"><tr><td>

<center><h2>
Why You Will Care: Lazy Programs</h2></ceNtEr>


<p>One way to see why
<a NaME="idx612"></a>exceptions are useful is to compare
coding styles in Python and languages without exceptions. For
instance, if you want to write robust programs in the C language, you
have to test return values or status codes after every operation that
could possibly go astray:</P>



<PrE cLASS="monofont">doStuff()
{                                  // C program:
     if (doFirstThing() == ERROR)  // must detect errors everywhere
          return ERROR;            // even if not processed here
     if (doNextThing() == ERROR)
          return ERROR;
     ...
     return doLastThing();
}

main()
{
     if (doStuff() == ERROR)
          badEnding();
     else
          goodEnding();
}</pre>

<p>In fact, realistic C programs have as much code devoted to error
detection as to doing actual work. But, in Python, you don't
have to be so methodical; instead you can wrap arbitrarily vast
pieces of a program in exception handlers and write the parts that do
the actual work to assume all is well:</P>


<PRE clasS="monofont">def doStuff():
     doFirstThing()           # we don't care about exceptions here
     doNextThing()            # so we don't need to detect them here
     ...
     doLastThing()

if__name__ == '__main__':
     try:
          doStuff()           # this is where we care about the result
     except:                  # so it's the only place we need to check
          badEnding()
     else:
          goodEnding()</PRE>

<p>Because control jumps immediately and automatically to a handler when
an exception occurs, there's no need to instrument all your
code to guard for errors. The upshot is that exceptions let you
largely ignore the unusual cases and avoid much error-checking code.</p>



</td></TR></TAble></p>


</font>
 
<table width="100%" border="0" cellspacing="0" cellpadding="0" bgcolor="#CCCCCC">
<td><font color="black" size=1>I l<font color="#FF0000">@</font>ve RuBoard</td>
<td valign="top" class="v2" align="right"><a href="lpython_snode81.html"><img src="FILES/previous.gif" width="62" height="15" border="0" align="absmiddle" alt="Previous Section"></a> <a href="lpython_snode83.html"><img src="FILES/next.gif" width="41" height="15" border="0" align="absmiddle" alt="Next Section"></a></td></table>
</BODY></HTML>