<html><head>
<META http-equiv="Content-Type" content="text/html">
<!--SafClassName="docSection1Title"--><!--SafTocEntry="6.2 Exception Propagation"-->
<link rel="STYLESHEET" type="text/css" href="FILES/style.css">
<link rel="STYLESHEET" type="text/css" href="FILES/docsafari.css">
<style type="text/css">	.tt1    {font-size: 10pt;}</style>
</head>
<body>
<table width="100%" border="0" cellspacing="0" cellpadding="0">
<td class="tt1"><a href="NFO/lib.html">[ Team LiB ]</a></td><td valign="top" class="tt1" align="right">
	<a href="0596001886_pythonian-chp-6-sect-1.html"><img src="FILES/previous.gif" width="62" height="15" border="0" align="absmiddle" alt="Previous Section"></a>
	<a href="0596001886_pythonian-chp-6-sect-3.html"><img src="FILES/next.gif" width="41" height="15" border="0" align="absmiddle" alt="Next Section"></a>
</td></table>
<br>
<table width="100%" border="0" cellspacing="0" cellpadding="0">
<tr>
<td valign="top"><A NAME="pythonian-CHP-6-SECT-2"></A>
<H3 class="docSection1Title">6.2 Exception Propagation</H3>

<P class="docText"><A NAME="pythonian-CHP-6-ITERM-4565"></A> <A NAME="pythonian-CHP-6-ITERM-4566"></A>When an exception is raised, the
exception-propagation mechanism takes control. The normal control
flow of the program stops, and Python looks for a suitable exception
handler. Python's <TT>try</TT> statement
establishes exception handlers via its <TT>except</TT>
clauses. The handlers deal with exceptions raised in the body of the
<TT>try</TT> clause, as well as exceptions that propagate
from any of the functions called by that code, directly or
indirectly. If an exception is raised within a <TT>try</TT>
clause that has an applicable <TT>except</TT> handler, the
<TT>try</TT> clause terminates and the handler executes.
When the handler finishes, execution continues with the statement
after the <TT>try</TT> statement.</P>

<P class="docText">If the statement raising the exception is not within a
<TT>try</TT> clause that has an applicable handler, the
function containing the statement terminates, and the exception
propagates upward to the statement that called the function. If the
call to the terminated function is within a <TT>try</TT>
clause that has an applicable handler, that <TT>try</TT>
clause terminates, and the handler executes. Otherwise, the function
containing the call terminates, and the propagation process repeats,
unwinding the stack of function calls until an applicable handler is
found.</P>

<P class="docText"><A NAME="pythonian-CHP-6-ITERM-4567"></A>
<A NAME="pythonian-CHP-6-ITERM-4568"></A>If Python cannot find such a handler, by
default the program prints an error message to the standard error
stream (the file <TT>sys.stderr</TT>). The error message
includes a traceback that gives details about functions terminated
during propagation. You can change Python's default
error-reporting behavior by setting <TT>sys.excepthook</TT>
(covered in <A class="docLink" HREF="0596001886_pythonian-chp-8.html#pythonian-CHP-8">Chapter 8</A>). After error reporting,
Python goes back to the interactive session, if any, or terminates if
no interactive session is active. When the exception class is
<TT>SystemExit</TT>, termination is silent and includes the
interactive session, if any.<A NAME="pythonian-CHP-6-ITERM-4569"></A></P>

<P class="docText">Here are some functions that we can use to see exception propagation
at work.</P>

<PRE>def f(  ):
    print "in f, before 1/0"
    1/0                           # raises a ZeroDivisionError exception
    print "in f, after 1/0"

def g(  ):
    print "in g, before f(  )"
    f(  )
    print "in g, after f(  )"

def h(  ):
    print "in h, before g(  )"
    try:
        g(  )
        print "in h, after g(  )"
    except ZeroDivisionError:
        print "ZD exception caught"
    print "function h ends"</PRE>

<P class="docText">Calling the <TT>h</TT> function has the following results:</P>

<PRE>&gt;&gt;&gt; h(  )
<span class="docEmphBold">in h, before g(  )</span>
<span class="docEmphBold">in g, before f(  )</span>
<span class="docEmphBold">in f, before 1/0</span>
<span class="docEmphBold">ZD exception caught</span>
<span class="docEmphBold">function h ends</span></PRE>

<P class="docText">Function <TT>h</TT> establishes a <TT>try</TT>
statement and calls function <TT>g</TT> within the
<TT>try</TT> clause. <TT>g</TT>, in turn, calls
<TT>f</TT>, which performs a division by
<TT>0</TT>, raising an exception of class
<TT>ZeroDivisionError</TT>. The exception propagates all
the way back to the <TT>except</TT> clause in
<TT>h</TT>. Functions <TT>f</TT> and
<TT>g</TT> terminate during the exception propagation
phase, which is why neither of their
"after" messages is printed. The
execution of <TT>h</TT>'s
<TT>try</TT> clause also terminates during the exception
propagation phase, so its "after"
message isn't printed either. Execution continues
after the handler, at the end of
<TT>h</TT>'s
<TT>try</TT>/<TT>except</TT> block.</P>


<a href="0596001886_"><img src="FILES/pixel.gif" width="1" height="1" border="0"></a><ul></ul>
</td>
</tr>
</table>
<td></td>
<table width="100%" border="0" cellspacing="0" cellpadding="0">
<td class="tt1"><a href="NFO/lib.html">[ Team LiB ]</a></td><td valign="top" class="tt1" align="right">
          <a href="0596001886_pythonian-chp-6-sect-1.html"><img src="FILES/previous.gif" width="62" height="15" border="0" align="absmiddle" alt="Previous Section"></a>
          <a href="0596001886_pythonian-chp-6-sect-3.html"><img src="FILES/next.gif" width="41" height="15" border="0" align="absmiddle" alt="Next Section"></a>
</td></table>
</body></html>
